Workbook

Sheet Sheet1
A1: ETF DETAILS
A2: ='Daily Update'!B2 | B2: 46162
A4: ETF | B4: SYMBOL | C4: %age | D4: SYMBOL | E4: Acct Type | G4: Current Price | H4: Volume | I4: 1 Day Change % | J4: 5 Day Change % | K4: 1 Mos Change % | L4: 1 Year Change % | M4: 2 Year Change % | N4: 5 Year Change %
G5: =IF($B5="","",IFERROR(XLOOKUP($B5,'Daily Update'!$A:$A,'Daily Update'!$C:$C),"")) | H5: =IF($B5="","",IFERROR(XLOOKUP($B5,'Daily Update'!$A:$A,'Daily Update'!$D:$D),"")) | I5: =IF($B5="","",IFERROR(XLOOKUP($B5,'Daily Update'!$A:$A,'Daily Update'!$E:$E),"")) | J5: =IF($B5="","",IFERROR(XLOOKUP($B5,'Daily Update'!$A:$A,'Daily Update'!$F:$F),"")) | K5: =IF($B5="","",IFERROR(XLOOKUP($B5,'Daily Update'!$A:$A,'Daily Update'!$G:$G),"")) | L5: =IF($B5="","",IFERROR(XLOOKUP($B5,'Daily Update'!$A:$A,'Daily Update'!$H:$H),"")) | M5: =IF($B5="","",IFERROR(XLOOKUP($B5,'Daily Update'!$A:$A,'Daily Update'!$I:$I),"")) | N5: =IF($B5="","",IFERROR(XLOOKUP($B5,'Daily Update'!$A:$A,'Daily Update'!$J:$J),""))
A6: Berkshire Hathaway Inc | B6: BRKB | C6: 1 | D6: BRKB | E6: IRA | G6: 480.46 | H6: 5574031 | I6: -0.01621691 | J6: -0.00927912 | K6: 0.01238991 | L6: -0.06231586 | M6: 0.15234803 | N6: 0.67565296
G7: =IF($B7="","",IFERROR(XLOOKUP($B7,'Daily Update'!$A:$A,'Daily Update'!$C:$C),"")) | H7: =IF($B7="","",IFERROR(XLOOKUP($B7,'Daily Update'!$A:$A,'Daily Update'!$D:$D),"")) | I7: =IF($B7="","",IFERROR(XLOOKUP($B7,'Daily Update'!$A:$A,'Daily Update'!$E:$E),"")) | J7: =IF($B7="","",IFERROR(XLOOKUP($B7,'Daily Update'!$A:$A,'Daily Update'!$F:$F),"")) | K7: =IF($B7="","",IFERROR(XLOOKUP($B7,'Daily Update'!$A:$A,'Daily Update'!$G:$G),"")) | L7: =IF($B7="","",IFERROR(XLOOKUP($B7,'Daily Update'!$A:$A,'Daily Update'!$H:$H),"")) | M7: =IF($B7="","",IFERROR(XLOOKUP($B7,'Daily Update'!$A:$A,'Daily Update'!$I:$I),"")) | N7: =IF($B7="","",IFERROR(XLOOKUP($B7,'Daily Update'!$A:$A,'Daily Update'!$J:$J),""))
A8: ISHARES CORE HIGH DIVIDEND ETF | B8: HDV | C8: =SUM(C9:C19) | D8: HDV | E8: IRA | G8: 27.71 | H8: 2350436 | I8: 0.00471353 | J8: 0.01874994 | K8: 0.03441836 | L8: 0.22412885 | M8: 0.32704547 | N8: 0.68172165
A9: Merck & Co Inc | B9: MRK | C9: 0.0377 | D9: HDV | E9: IRA | G9: 114.24 | H9: 5209075 | I9: 0.01492538 | J9: 0.01664141 | K9: -0.04056439 | L9: 0.53295277 | M9: -0.07082237 | N9: 0.7590783
A10: Progressive Corp | B10: PGR | C10: 0.0379 | D10: HDV | E10: IRA | G10: 202.87 | H10: 2457538 | I10: -0.00553924 | J10: 0.02242716 | K10: 0.0014315 | L10: -0.25049085 | M10: 0.05375258 | N10: 1.223539
A11: Coca-Cola Co | B11: KO | C11: 0.0386 | D11: HDV | E11: IRA | G11: 81.92 | H11: 16586904 | I11: 0.00886701 | J11: 0.02361614 | K11: 0.08159494 | L11: 0.17189977 | M11: 0.37737433 | N11: 0.73980952
A12: The Home Depot Inc | B12: HD | C12: 0.0407 | D12: HDV | E12: IRA | G12: 302.44 | H12: 8678246 | I12: 0.00877224 | J12: -0.0258326 | K12: -0.13440181 | L12: -0.18265378 | M12: -0.07674027 | N12: 0.08184457
A13: Philip Morris International Inc | B13: PM | C13: 0.0417 | D13: HDV | E13: IRA | G13: 191.57 | H13: 3749166 | I13: 0.00036557 | J13: 0.02482221 | K13: 0.21408211 | L13: 0.14545238 | M13: 1.0761645 | N13: 1.4935167
A14: Procter & Gamble Co | B14: PG | C14: 0.0446 | D14: HDV | E14: IRA | G14: 141.3 | H14: 4715632 | I14: -0.00765501 | J14: -0.01813634 | K14: -0.03107603 | L14: -0.11777187 | M14: -0.11167802 | N14: 0.16290085
A15: AbbVie Inc | B15: ABBV | C15: 0.0544 | D15: HDV | E15: IRA | G15: 213.76 | H15: 4460380 | I15: 0.0207726 | J15: 0.02838446 | K15: 0.02581817 | L15: 0.1885406 | M15: 0.37448755 | N15: 1.2017402
A16: Johnson & Johnson | B16: JNJ | C16: 0.0568 | D16: HDV | E16: IRA | G16: 230 | H16: 6002888 | I16: 0.00471781 | J16: 0.02559532 | K16: -0.01784949 | L16: 0.5503196 | M16: 0.57780938 | N16: 0.54825663
A17: Chevron Corp | B17: CVX | C17: 0.0642 | D17: HDV | E17: IRA | G17: 197.25 | H17: 11811800 | I17: 0.0057618 | J17: 0.06076904 | K17: 0.0720691 | L17: 0.47047527 | M17: 0.30875537 | N17: 1.3171999
A18: Exxon Mobil Corp | B18: XOM | C18: 0.0842 | D18: HDV | E18: IRA | G18: 162.55 | H18: 20706800 | I18: 0.01283568 | J18: 0.08645887 | K18: 0.11754512 | L18: 0.57538721 | M18: 0.45085385 | N18: 2.3201354
A19: Other | B19: OTH | C19: =100%-(SUM(C9:C18)) | D19: HDV | E19: IRA | G19: =IF($B19="","",IFERROR(XLOOKUP($B19,'Daily Update'!$A:$A,'Daily Update'!$C:$C),"")) | H19: =IF($B19="","",IFERROR(XLOOKUP($B19,'Daily Update'!$A:$A,'Daily Update'!$D:$D),"")) | I19: =IF($B19="","",IFERROR(XLOOKUP($B19,'Daily Update'!$A:$A,'Daily Update'!$E:$E),"")) | J19: =IF($B19="","",IFERROR(XLOOKUP($B19,'Daily Update'!$A:$A,'Daily Update'!$F:$F),"")) | K19: =IF($B19="","",IFERROR(XLOOKUP($B19,'Daily Update'!$A:$A,'Daily Update'!$G:$G),"")) | L19: =IF($B19="","",IFERROR(XLOOKUP($B19,'Daily Update'!$A:$A,'Daily Update'!$H:$H),"")) | M19: =IF($B19="","",IFERROR(XLOOKUP($B19,'Daily Update'!$A:$A,'Daily Update'!$I:$I),"")) | N19: =IF($B19="","",IFERROR(XLOOKUP($B19,'Daily Update'!$A:$A,'Daily Update'!$J:$J),""))
G20: =IF($B20="","",IFERROR(XLOOKUP($B20,'Daily Update'!$A:$A,'Daily Update'!$C:$C),"")) | H20: =IF($B20="","",IFERROR(XLOOKUP($B20,'Daily Update'!$A:$A,'Daily Update'!$D:$D),"")) | I20: =IF($B20="","",IFERROR(XLOOKUP($B20,'Daily Update'!$A:$A,'Daily Update'!$E:$E),"")) | J20: =IF($B20="","",IFERROR(XLOOKUP($B20,'Daily Update'!$A:$A,'Daily Update'!$F:$F),"")) | K20: =IF($B20="","",IFERROR(XLOOKUP($B20,'Daily Update'!$A:$A,'Daily Update'!$G:$G),"")) | L20: =IF($B20="","",IFERROR(XLOOKUP($B20,'Daily Update'!$A:$A,'Daily Update'!$H:$H),"")) | M20: =IF($B20="","",IFERROR(XLOOKUP($B20,'Daily Update'!$A:$A,'Daily Update'!$I:$I),"")) | N20: =IF($B20="","",IFERROR(XLOOKUP($B20,'Daily Update'!$A:$A,'Daily Update'!$J:$J),""))
A21: WEDBUSH SERIES TRUST DAN IVES WEDBUSH AI REVOLUTION ETF | B21: IVES | C21: =SUM(C22:C32) | D21: IVES | E21: IRA | G21: 35.76 | H21: 399100 | I21: -0.01024087 | J21: -0.00556176 | K21: 0.09290944
A22: GE Vernova Inc | B22: GEV | C22: 0.0424 | D22: IVES | E22: IRA | G22: 1011.8 | H22: 2243200 | I22: -0.00044457 | J22: -0.0561391 | K22: 0.00902517 | L22: 1.2705348 | M22: 5.2449684
A23: Microsoft Corp | B23: MSFT | C23: 0.0444 | D23: IVES | E23: IRA | G23: 417.42 | H23: 32942800 | I23: -0.01444963 | J23: 0.02366536 | K23: -0.01270133 | L23: -0.08504617 | M23: 0.00679123 | N23: 0.76083236
A24: Micron Technology Inc | B24: MU | C24: 0.0466 | D24: IVES | E24: IRA | G24: 698.74 | H24: 61450300 | I24: 0.02523698 | J24: -0.08849699 | K24: 0.53545604 | L24: 6.0999745 | M24: 4.6161004 | N24: 7.8308338
A25: Apple Inc | B25: AAPL | C25: 0.0471 | D25: IVES | E25: IRA | G25: 298.97 | H25: 42199700 | I25: 0.003794 | J25: 0.01414523 | K25: 0.10737315 | L25: 0.43766669 | M25: 0.58824366 | N25: 1.4091896
A26: NVIDIA Corp | B26: NVDA | C26: 0.0484 | D26: IVES | E26: IRA | G26: 220.61 | H26: 140201600 | I26: -0.00769165 | J26: -0.00076999 | K26: 0.09386161 | L26: 0.62766095 | M26: 1.3868608 | N26: 14.135398
A27: Taiwan Semiconductor Manufacturing Co Ltd ADR | B27: TSM | C27: 0.0494 | D27: IVES | E27: IRA | G27: 392.61 | H27: 14054400 | I27: -0.00843548 | J27: -0.01175497 | K27: 0.05967607 | L27: 1.0541221 | M27: 1.657129 | N27: 2.7654654
A28: Alphabet Inc Class A | B28: GOOGL | C28: 0.0538 | D28: IVES | E28: IRA | G28: 387.66 | H28: 39458400 | I28: -0.02337884 | J28: 0.0008003 | K28: 0.13457039 | L28: 1.3358006 | M28: 1.2200616 | N28: 2.3885783
A29: Amazon.com Inc | B29: AMZN | C29: 0.0542 | D29: IVES | E29: IRA | G29: 259.34 | H29: 40269100 | I29: -0.02084116 | J29: -0.02437744 | K29: 0.0350415 | L29: 0.25795495 | M29: 0.40411478 | N29: 0.59707848
A30: Broadcom Inc | B30: AVGO | C30: 0.0544 | D30: IVES | E30: IRA | G30: 411.07 | H30: 20620900 | I30: -0.02291361 | J30: -0.01962791 | K30: 0.01114281 | L30: 0.79682048 | M30: 2.0063057 | N30: 8.9857326
A31: Advanced Micro Devices Inc | B31: AMD | C31: 0.0633 | D31: IVES | E31: IRA | G31: 414.05 | H31: 38637700 | I31: -0.01648496 | J31: -0.07637917 | K31: 0.48730186 | L31: 2.6085933 | M31: 1.5174803 | N31: 4.3042532
A32: Other | B32: OTH | C32: =100%-(SUM(C22:C31)) | D32: IVES | E32: IRA | G32: =IF($B32="","",IFERROR(XLOOKUP($B32,'Daily Update'!$A:$A,'Daily Update'!$C:$C),"")) | H32: =IF($B32="","",IFERROR(XLOOKUP($B32,'Daily Update'!$A:$A,'Daily Update'!$D:$D),"")) | I32: =IF($B32="","",IFERROR(XLOOKUP($B32,'Daily Update'!$A:$A,'Daily Update'!$E:$E),"")) | J32: =IF($B32="","",IFERROR(XLOOKUP($B32,'Daily Update'!$A:$A,'Daily Update'!$F:$F),"")) | K32: =IF($B32="","",IFERROR(XLOOKUP($B32,'Daily Update'!$A:$A,'Daily Update'!$G:$G),"")) | L32: =IF($B32="","",IFERROR(XLOOKUP($B32,'Daily Update'!$A:$A,'Daily Update'!$H:$H),"")) | M32: =IF($B32="","",IFERROR(XLOOKUP($B32,'Daily Update'!$A:$A,'Daily Update'!$I:$I),"")) | N32: =IF($B32="","",IFERROR(XLOOKUP($B32,'Daily Update'!$A:$A,'Daily Update'!$J:$J),""))
G33: =IF($B33="","",IFERROR(XLOOKUP($B33,'Daily Update'!$A:$A,'Daily Update'!$C:$C),"")) | H33: =IF($B33="","",IFERROR(XLOOKUP($B33,'Daily Update'!$A:$A,'Daily Update'!$D:$D),"")) | I33: =IF($B33="","",IFERROR(XLOOKUP($B33,'Daily Update'!$A:$A,'Daily Update'!$E:$E),"")) | J33: =IF($B33="","",IFERROR(XLOOKUP($B33,'Daily Update'!$A:$A,'Daily Update'!$F:$F),"")) | K33: =IF($B33="","",IFERROR(XLOOKUP($B33,'Daily Update'!$A:$A,'Daily Update'!$G:$G),"")) | L33: =IF($B33="","",IFERROR(XLOOKUP($B33,'Daily Update'!$A:$A,'Daily Update'!$H:$H),"")) | M33: =IF($B33="","",IFERROR(XLOOKUP($B33,'Daily Update'!$A:$A,'Daily Update'!$I:$I),"")) | N33: =IF($B33="","",IFERROR(XLOOKUP($B33,'Daily Update'!$A:$A,'Daily Update'!$J:$J),""))
A34: NEOS ETF TR NEOS RUSSELL 2000 HIGH INCOME ETF | B34: IWMI | C34: =SUM(C35:C36) | D34: IWMI | E34: IRA | G34: 50.4 | H34: 338400 | I34: -0.00923919 | J34: -0.02740251 | K34: -0.00467414 | L34: 0.29223417
A35: First American Treasury Obligs X | B35: FXFXX | C35: 0.0044925277 | D35: IWMI | E35: IRA | G35: 1
A36: Vanguard Russell 2000 ETF | B36: VTWO | C36: 0.99550747 | D36: IWMI | E36: IRA | G36: 110.32 | H36: 2337100 | I36: -0.01067171 | J36: -0.03380628 | K36: -0.00996142 | L36: 0.32343842 | M36: 0.3467783 | N36: 0.33418223
G37: =IF($B37="","",IFERROR(XLOOKUP($B37,'Daily Update'!$A:$A,'Daily Update'!$C:$C),"")) | H37: =IF($B37="","",IFERROR(XLOOKUP($B37,'Daily Update'!$A:$A,'Daily Update'!$D:$D),"")) | I37: =IF($B37="","",IFERROR(XLOOKUP($B37,'Daily Update'!$A:$A,'Daily Update'!$E:$E),"")) | J37: =IF($B37="","",IFERROR(XLOOKUP($B37,'Daily Update'!$A:$A,'Daily Update'!$F:$F),"")) | K37: =IF($B37="","",IFERROR(XLOOKUP($B37,'Daily Update'!$A:$A,'Daily Update'!$G:$G),"")) | L37: =IF($B37="","",IFERROR(XLOOKUP($B37,'Daily Update'!$A:$A,'Daily Update'!$H:$H),"")) | M37: =IF($B37="","",IFERROR(XLOOKUP($B37,'Daily Update'!$A:$A,'Daily Update'!$I:$I),"")) | N37: =IF($B37="","",IFERROR(XLOOKUP($B37,'Daily Update'!$A:$A,'Daily Update'!$J:$J),""))
A38: LISTED FUNDS TRUST ROUNDHILL MAGNIFICENT SEVEN ETF | B38: MAGS | C38: =SUM(C39:C49) | D38: MAGS | E38: IRA | G38: 68.53 | H38: 2829500 | I38: -0.01338901 | J38: -0.00853594 | K38: 0.03130176 | L38: 0.33032396 | M38: 0.71899593
A39: United States Treasury Bills 0% | C39: 0.4212 | D39: MAGS | E39: IRA | G39: =IF($B39="","",IFERROR(XLOOKUP($B39,'Daily Update'!$A:$A,'Daily Update'!$C:$C),"")) | H39: =IF($B39="","",IFERROR(XLOOKUP($B39,'Daily Update'!$A:$A,'Daily Update'!$D:$D),"")) | I39: =IF($B39="","",IFERROR(XLOOKUP($B39,'Daily Update'!$A:$A,'Daily Update'!$E:$E),"")) | J39: =IF($B39="","",IFERROR(XLOOKUP($B39,'Daily Update'!$A:$A,'Daily Update'!$F:$F),"")) | K39: =IF($B39="","",IFERROR(XLOOKUP($B39,'Daily Update'!$A:$A,'Daily Update'!$G:$G),"")) | L39: =IF($B39="","",IFERROR(XLOOKUP($B39,'Daily Update'!$A:$A,'Daily Update'!$H:$H),"")) | M39: =IF($B39="","",IFERROR(XLOOKUP($B39,'Daily Update'!$A:$A,'Daily Update'!$I:$I),"")) | N39: =IF($B39="","",IFERROR(XLOOKUP($B39,'Daily Update'!$A:$A,'Daily Update'!$J:$J),""))
A40: Meta Platforms Inc Class A | B40: META | C40: 0.0531 | D40: MAGS | E40: IRA | G40: 602.61 | H40: 11720900 | I40: -0.01407051 | J40: -0.00064679 | K40: -0.12481302 | L40: -0.05611858 | M40: 0.28561643 | N40: 0.90621436
A41: ALPHABET INC-CL A SWAP | C41: 0.0531 | D41: MAGS | E41: IRA | G41: =IF($B41="","",IFERROR(XLOOKUP($B41,'Daily Update'!$A:$A,'Daily Update'!$C:$C),"")) | H41: =IF($B41="","",IFERROR(XLOOKUP($B41,'Daily Update'!$A:$A,'Daily Update'!$D:$D),"")) | I41: =IF($B41="","",IFERROR(XLOOKUP($B41,'Daily Update'!$A:$A,'Daily Update'!$E:$E),"")) | J41: =IF($B41="","",IFERROR(XLOOKUP($B41,'Daily Update'!$A:$A,'Daily Update'!$F:$F),"")) | K41: =IF($B41="","",IFERROR(XLOOKUP($B41,'Daily Update'!$A:$A,'Daily Update'!$G:$G),"")) | L41: =IF($B41="","",IFERROR(XLOOKUP($B41,'Daily Update'!$A:$A,'Daily Update'!$H:$H),"")) | M41: =IF($B41="","",IFERROR(XLOOKUP($B41,'Daily Update'!$A:$A,'Daily Update'!$I:$I),"")) | N41: =IF($B41="","",IFERROR(XLOOKUP($B41,'Daily Update'!$A:$A,'Daily Update'!$J:$J),""))
...

Sheet Daily Update
A1: Daily ETF / Holding Update Interface
A2: Workbook last updated: | B2: 46162
A3: Enter or paste today's market data into the yellow columns. Sheet1 columns G:N will update automatically by matching each row's SYMBOL. Leave unavailable fields blank.
A5: Ticker | B5: Security / ETF Name | C5: Current Price | D5: Volume | E5: 1 Day Change % | F5: 5 Day Change % | G5: 1 Mos Change % | H5: 1 Year Change % | I5: 2 Year Change % | J5: 5 Year Change % | K5: Last Updated | L5: Source / Notes
A6: BRKB | B6: Berkshire Hathaway Inc | C6: 480.46 | D6: 5586100 | E6: -0.01621691 | F6: -0.00927912 | G6: 0.01238991 | H6: -0.06231586 | I6: 0.15234803 | J6: 0.67565296 | K6: 2026-05-20 04:13 | L6: yfinance
A7: HDV | B7: ISHARES CORE HIGH DIVIDEND ETF | C7: 27.71 | D7: 2370100 | E7: 0.00471353 | F7: 0.01874994 | G7: 0.03441836 | H7: 0.22412885 | I7: 0.32704534 | J7: 0.68172185 | K7: 2026-05-20 04:13 | L7: yfinance
A8: MRK | B8: Merck & Co Inc | C8: 114.24 | D8: 7550400 | E8: 0.01492538 | F8: 0.01664141 | G8: -0.04056439 | H8: 0.53295262 | I8: -0.07082231 | J8: 0.75907851 | K8: 2026-05-20 04:13 | L8: yfinance
A9: PGR | B9: Progressive Corp | C9: 202.87 | D9: 2577200 | E9: -0.00553924 | F9: 0.02242716 | G9: 0.0014315 | H9: -0.25049085 | I9: 0.05375258 | J9: 1.223539 | K9: 2026-05-20 04:13 | L9: yfinance
A10: KO | B10: Coca-Cola Co | C10: 81.92 | D10: 16587900 | E10: 0.00886701 | F10: 0.02361614 | G10: 0.08159494 | H10: 0.1718999 | I10: 0.37737398 | J10: 0.73981008 | K10: 2026-05-20 04:13 | L10: yfinance
A11: HD | B11: The Home Depot Inc | C11: 302.44 | D11: 8682700 | E11: 0.00877224 | F11: -0.0258326 | G11: -0.13440181 | H11: -0.18265385 | I11: -0.07674018 | J11: 0.08184457 | K11: 2026-05-20 04:13 | L11: yfinance
A12: PM | B12: Philip Morris International Inc | C12: 191.57 | D12: 5741500 | E12: 0.00036557 | F12: 0.02482221 | G12: 0.21408211 | H12: 0.14545249 | I12: 1.0761647 | J12: 1.4935167 | K12: 2026-05-20 04:13 | L12: yfinance
A13: PG | B13: Procter & Gamble Co | C13: 141.3 | D13: 8351900 | E13: -0.00765501 | F13: -0.01813634 | G13: -0.03107603 | H13: -0.11777178 | I13: -0.11167793 | J13: 0.16290077 | K13: 2026-05-20 04:13 | L13: yfinance
A14: ABBV | B14: AbbVie Inc | C14: 213.76 | D14: 7217400 | E14: 0.0207726 | F14: 0.02838446 | G14: 0.02581817 | H14: 0.1885406 | I14: 0.37448755 | J14: 1.2017404 | K14: 2026-05-20 04:13 | L14: yfinance
A15: JNJ | B15: Johnson & Johnson | C15: 230 | D15: 9668500 | E15: 0.00471781 | F15: 0.02559532 | G15: -0.01784949 | H15: 0.5503196 | I15: 0.57780938 | J15: 0.54825631 | K15: 2026-05-20 04:13 | L15: yfinance
A16: CVX | B16: Chevron Corp | C16: 197.25 | D16: 11811800 | E16: 0.0057618 | F16: 0.06076904 | G16: 0.0720691 | H16: 0.47047543 | I16: 0.30875551 | J16: 1.3172001 | K16: 2026-05-20 04:13 | L16: yfinance
A17: XOM | B17: Exxon Mobil Corp | C17: 162.55 | D17: 20706800 | E17: 0.01283568 | F17: 0.08645887 | G17: 0.11754512 | H17: 0.57538721 | I17: 0.45085385 | J17: 2.3201362 | K17: 2026-05-20 04:13 | L17: yfinance
A18: IVES | B18: WEDBUSH SERIES TRUST DAN IVES WEDBUSH AI REVOLUTION ETF | C18: 35.76 | D18: 399100 | E18: -0.01024087 | F18: -0.00556176 | G18: 0.09290944 | K18: 2026-05-20 04:13 | L18: yfinance
A19: GEV | B19: GE Vernova Inc | C19: 1011.8 | D19: 2243200 | E19: -0.00044457 | F19: -0.0561391 | G19: 0.00902517 | H19: 1.2705349 | I19: 5.2449684 | K19: 2026-05-20 04:13 | L19: yfinance
A20: MSFT | B20: Microsoft Corp | C20: 417.42 | D20: 32942800 | E20: -0.01444963 | F20: 0.02366536 | G20: -0.01270133 | H20: -0.08504617 | I20: 0.00679138 | J20: 0.76083213 | K20: 2026-05-20 04:13 | L20: yfinance
A21: MU | B21: Micron Technology Inc | C21: 698.74 | D21: 61450300 | E21: 0.02523698 | F21: -0.08849699 | G21: 0.53545604 | H21: 6.0999745 | I21: 4.6161004 | J21: 7.8308329 | K21: 2026-05-20 04:13 | L21: yfinance
A22: AAPL | B22: Apple Inc | C22: 298.97 | D22: 42199700 | E22: 0.003794 | F22: 0.01414523 | G22: 0.10737315 | H22: 0.43766669 | I22: 0.58824353 | J22: 1.40919 | K22: 2026-05-20 04:13 | L22: yfinance
A23: NVDA | B23: NVIDIA Corp | C23: 220.61 | D23: 140201600 | E23: -0.00769165 | F23: -0.00076999 | G23: 0.09386161 | H23: 0.62766095 | I23: 1.3868611 | J23: 14.1354 | K23: 2026-05-20 04:13 | L23: yfinance
A24: TSM | B24: Taiwan Semiconductor Manufacturing Co Ltd ADR | C24: 392.61 | D24: 14054400 | E24: -0.00843548 | F24: -0.01175497 | G24: 0.05967607 | H24: 1.0541225 | I24: 1.657129 | J24: 2.7654654 | K24: 2026-05-20 04:13 | L24: yfinance
A25: GOOGL | B25: Alphabet Inc Class A | C25: 387.66 | D25: 39458400 | E25: -0.02337884 | F25: 0.0008003 | G25: 0.13457039 | H25: 1.3358006 | I25: 1.220061 | J25: 2.3885778 | K25: 2026-05-20 04:13 | L25: yfinance
A26: AMZN | B26: Amazon.com Inc | C26: 259.34 | D26: 40269100 | E26: -0.02084116 | F26: -0.02437744 | G26: 0.0350415 | H26: 0.25795495 | I26: 0.40411478 | J26: 0.59707848 | K26: 2026-05-20 04:13 | L26: yfinance
A27: AVGO | B27: Broadcom Inc | C27: 411.07 | D27: 20620900 | E27: -0.02291361 | F27: -0.01962791 | G27: 0.01114281 | H27: 0.79682048 | I27: 2.006306 | J27: 8.9857308 | K27: 2026-05-20 04:13 | L27: yfinance
A28: AMD | B28: Advanced Micro Devices Inc | C28: 414.05 | D28: 38637700 | E28: -0.01648496 | F28: -0.07637917 | G28: 0.48730186 | H28: 2.6085933 | I28: 1.5174803 | J28: 4.3042532 | K28: 2026-05-20 04:13 | L28: yfinance
A29: IWMI | B29: NEOS ETF TR NEOS RUSSELL 2000 HIGH INCOME ETF | C29: 50.4 | D29: 338400 | E29: -0.00923919 | F29: -0.02740251 | G29: -0.00467414 | H29: 0.29223429 | K29: 2026-05-20 04:13 | L29: yfinance
A30: FXFXX | B30: First American Treasury Obligs X | C30: 1 | K30: 2026-05-20 04:13 | L30: fixed $1.00
A31: VTWO | B31: Vanguard Russell 2000 ETF | C31: 110.32 | D31: 2337100 | E31: -0.01067171 | F31: -0.03380628 | G31: -0.00996142 | H31: 0.32343854 | I31: 0.3467783 | J31: 0.33418223 | K31: 2026-05-20 04:13 | L31: yfinance
A32: MAGS | B32: LISTED FUNDS TRUST ROUNDHILL MAGNIFICENT SEVEN ETF | C32: 68.53 | D32: 2829500 | E32: -0.01338901 | F32: -0.00853594 | G32: 0.03130176 | H32: 0.33032396 | I32: 0.71899593 | K32: 2026-05-20 04:13 | L32: yfinance
A33: META | B33: Meta Platforms Inc Class A | C33: 602.61 | D33: 11720900 | E33: -0.01407051 | F33: -0.00064679 | G33: -0.12481302 | H33: -0.05611858 | I33: 0.28561635 | J33: 0.90621418 | K33: 2026-05-20 04:13 | L33: yfinance
A34: XBOX | B34: Roundhill Ultra Shrt Dur No Div TrgtETF | C34: 99.53 | D34: 32700 | E34: 0 | F34: 0.00090503 | G34: 0.00241714 | K34: 2026-05-20 04:13 | L34: yfinance
A35: QQQI | B35: NEOS ETF TRUST NEOS NASDAQ 100 HIGH INCOME ETF | C35: 56.14 | D35: 7640900 | E35: -0.00354989 | F35: -0.00319603 | G35: 0.05412315 | H35: 0.2700307 | I35: 0.46685105 | K35: 2026-05-20 04:13 | L35: yfinance
A36: TSLA | B36: Tesla Inc | C36: 404.11 | D36: 46354700 | E36: -0.01434183 | F36: -0.06768953 | G36: 0.00871147 | H36: 0.18129729 | I36: 1.2771891 | J36: 1.0660723 | K36: 2026-05-20 04:13 | L36: yfinance
A37: GOOG | B37: Alphabet Inc Class C | C37: 384.9 | D37: 25497700 | E37: -0.02088472 | F37: 0.00281378 | G37: 0.13406011 | H37: 1.3007722 | I37: 1.1888433 | J37: 2.2941017 | K37: 2026-05-20 04:13 | L37: yfinance
A38: QTUM | B38: ETF SER SOLUTIONS DEFIANCE QUANTUM ETF | C38: 140.63 | D38: 528600 | E38: -0.00943859 | F38: -0.02326706 | G38: 0.0996169 | H38: 0.67591539 | I38: 1.3275651 | J38: 2.1806808 | K38: 2026-05-20 04:13 | L38: yfinance
A39: COHR | B39: Coherent Corp | C39: 353.63 | D39: 5771600 | E39: -0.02535618 | F39: -0.05449053 | G39: 0.02495512 | H39: 3.4549007 | I39: 5.0834337 | J39: 4.3669754 | K39: 2026-05-20 04:13 | L39: yfinance
A40: ONTO | B40: Onto Innovation Inc | C40: 248.08 | D40: 4992400 | E40: -0.02534081 | F40: -0.10743326 | G40: -0.14678775 | H40: 1.4704243 | I40: 0.10997764 | J40: 2.8780678 | K40: 2026-05-20 04:13 | L40: yfinance
A41: MRVL | B41: Marvell Technology Inc | C41: 176.27 | D41: 24916400 | E41: 0.04345002 | F41: 0.07155018 | G41: 0.26186557 | H41: 1.8252325 | I41: 1.4656723 | J41: 2.8849935 | K41: 2026-05-20 04:13 | L41: yfinance
...

Sheet How to Update
A1: Daily Update Process
A3: Step | B3: What to do | C3: Where | D3: Notes
A4: 1 | B4: Open the Daily Update sheet. | C4: Daily Update | D4: Only edit the yellow columns.
A5: 2 | B5: Update the Workbook last updated date if needed. | C5: Daily Update!B2 | D5: It currently uses =TODAY(), so it changes automatically when opened.
A6: 3 | B6: Paste or type market data for each ticker. | C6: Daily Update columns C:J | D6: Use decimals for percentages if Excel does not auto-convert: 1.5% = 0.015.
A7: 4 | B7: Enter Last Updated and Source/Notes. | C7: Daily Update columns K:L | D7: This helps you know which rows were refreshed.
A8: 5 | B8: Return to Sheet1. | C8: Sheet1 columns G:N | D8: Those columns pull from Daily Update using ticker matching.
A9: 6 | B9: Check the checklist. | C9: Daily Update bottom section | D9: Missing price count should be 0 when your update is complete.
